2020-06-19 23:33:58,066 INFO: GPB startup [in C:\Users\super\OneDrive\Рабочий стол\versions\gazprombank\app\__init__.py:83]
2020-06-19 23:37:33,589 INFO: GPB startup [in C:\Users\super\OneDrive\Рабочий стол\versions\gazprombank\app\__init__.py:83]
2020-06-20 16:20:15,038 INFO: GPB startup [in C:\Users\super\OneDrive\Рабочий стол\versions\gazprombank\app\__init__.py:83]
2020-06-20 16:21:18,443 INFO: GPB startup [in C:\Users\super\OneDrive\Рабочий стол\versions\gazprombank\app\__init__.py:83]
2020-06-20 16:22:36,953 INFO: GPB startup [in C:\Users\super\OneDrive\Рабочий стол\versions\gazprombank\app\__init__.py:83]
2020-06-20 16:23:52,293 INFO: GPB startup [in C:\Users\super\OneDrive\Рабочий стол\versions\gazprombank\app\__init__.py:83]
2020-06-20 16:27:12,631 INFO: GPB startup [in C:\Users\super\OneDrive\Рабочий стол\versions\gazprombank\app\__init__.py:83]
2020-06-20 16:27:46,533 INFO: GPB startup [in C:\Users\super\OneDrive\Рабочий стол\versions\gazprombank\app\__init__.py:83]
2020-06-20 16:29:40,695 INFO: GPB startup [in C:\Users\super\OneDrive\Рабочий стол\versions\gazprombank\app\__init__.py:83]
2020-06-20 16:34:33,265 INFO: GPB startup [in C:\Users\super\OneDrive\Рабочий стол\versions\gazprombank\app\__init__.py:83]
2020-06-20 16:35:22,503 INFO: GPB startup [in C:\Users\super\OneDrive\Рабочий стол\versions\gazprombank\app\__init__.py:83]
2020-06-20 16:37:41,905 INFO: GPB startup [in C:\Users\super\OneDrive\Рабочий стол\versions\gazprombank\app\__init__.py:83]
2020-06-20 16:44:23,326 INFO: GPB startup [in C:\Users\super\OneDrive\Рабочий стол\versions\gazprombank\app\__init__.py:83]
2020-06-20 16:45:25,804 INFO: GPB startup [in C:\Users\super\OneDrive\Рабочий стол\versions\gazprombank\app\__init__.py:83]
2020-06-20 16:46:34,117 INFO: GPB startup [in C:\Users\super\OneDrive\Рабочий стол\versions\gazprombank\app\__init__.py:83]
2020-06-20 16:47:02,342 INFO: GPB startup [in C:\Users\super\OneDrive\Рабочий стол\versions\gazprombank\app\__init__.py:83]
2020-06-20 16:47:47,705 INFO: GPB startup [in C:\Users\super\OneDrive\Рабочий стол\versions\gazprombank\app\__init__.py:83]
2020-06-20 16:48:30,060 INFO: GPB startup [in C:\Users\super\OneDrive\Рабочий стол\versions\gazprombank\app\__init__.py:83]
2020-06-20 16:50:39,251 INFO: GPB startup [in C:\Users\super\OneDrive\Рабочий стол\versions\gazprombank\app\__init__.py:83]
2020-06-20 16:54:07,992 INFO: GPB startup [in C:\Users\super\OneDrive\Рабочий стол\versions\gazprombank\app\__init__.py:83]
2020-06-20 16:55:40,075 INFO: GPB startup [in C:\Users\super\OneDrive\Рабочий стол\versions\gazprombank\app\__init__.py:83]
2020-06-20 16:59:14,535 INFO: GPB startup [in C:\Users\super\OneDrive\Рабочий стол\versions\gazprombank\app\__init__.py:83]
2020-06-20 16:59:17,745 ERROR: Exception on /user/Scorpic [GET] [in c:\users\super\knowland\knowland_start\lib\site-packages\flask\app.py:1890]
Traceback (most recent call last):
  File "c:\users\super\knowland\knowland_start\lib\site-packages\sqlalchemy\engine\base.py", line 1247, in _execute_context
    self.dialect.do_execute(
  File "c:\users\super\knowland\knowland_start\lib\site-packages\sqlalchemy\engine\default.py", line 588, in do_execute
    cursor.execute(statement, parameters)
sqlite3.OperationalError: no such column: user.gpb_coin

The above exception was the direct cause of the following exception:

Traceback (most recent call last):
  File "c:\users\super\knowland\knowland_start\lib\site-packages\flask\app.py", line 2446, in wsgi_app
    response = self.full_dispatch_request()
  File "c:\users\super\knowland\knowland_start\lib\site-packages\flask\app.py", line 1951, in full_dispatch_request
    rv = self.handle_user_exception(e)
  File "c:\users\super\knowland\knowland_start\lib\site-packages\flask\app.py", line 1820, in handle_user_exception
    reraise(exc_type, exc_value, tb)
  File "c:\users\super\knowland\knowland_start\lib\site-packages\flask\_compat.py", line 39, in reraise
    raise value
  File "c:\users\super\knowland\knowland_start\lib\site-packages\flask\app.py", line 1947, in full_dispatch_request
    rv = self.preprocess_request()
  File "c:\users\super\knowland\knowland_start\lib\site-packages\flask\app.py", line 2241, in preprocess_request
    rv = func()
  File "C:\Users\super\OneDrive\Рабочий стол\versions\gazprombank\app\main\routes.py", line 18, in before_request
    if current_user.is_authenticated:
  File "c:\users\super\knowland\knowland_start\lib\site-packages\werkzeug\local.py", line 347, in __getattr__
    return getattr(self._get_current_object(), name)
  File "c:\users\super\knowland\knowland_start\lib\site-packages\werkzeug\local.py", line 306, in _get_current_object
    return self.__local()
  File "c:\users\super\knowland\knowland_start\lib\site-packages\flask_login\utils.py", line 26, in <lambda>
    current_user = LocalProxy(lambda: _get_user())
  File "c:\users\super\knowland\knowland_start\lib\site-packages\flask_login\utils.py", line 346, in _get_user
    current_app.login_manager._load_user()
  File "c:\users\super\knowland\knowland_start\lib\site-packages\flask_login\login_manager.py", line 318, in _load_user
    user = self._user_callback(user_id)
  File "C:\Users\super\OneDrive\Рабочий стол\versions\gazprombank\app\models.py", line 128, in load_user
    return User.query.get(int(id))
  File "c:\users\super\knowland\knowland_start\lib\site-packages\sqlalchemy\orm\query.py", line 1004, in get
    return self._get_impl(ident, loading.load_on_pk_identity)
  File "c:\users\super\knowland\knowland_start\lib\site-packages\sqlalchemy\orm\query.py", line 1119, in _get_impl
    return db_load_fn(self, primary_key_identity)
  File "c:\users\super\knowland\knowland_start\lib\site-packages\sqlalchemy\orm\loading.py", line 284, in load_on_pk_identity
    return q.one()
  File "c:\users\super\knowland\knowland_start\lib\site-packages\sqlalchemy\orm\query.py", line 3358, in one
    ret = self.one_or_none()
  File "c:\users\super\knowland\knowland_start\lib\site-packages\sqlalchemy\orm\query.py", line 3327, in one_or_none
    ret = list(self)
  File "c:\users\super\knowland\knowland_start\lib\site-packages\sqlalchemy\orm\query.py", line 3403, in __iter__
    return self._execute_and_instances(context)
  File "c:\users\super\knowland\knowland_start\lib\site-packages\sqlalchemy\orm\query.py", line 3428, in _execute_and_instances
    result = conn.execute(querycontext.statement, self._params)
  File "c:\users\super\knowland\knowland_start\lib\site-packages\sqlalchemy\engine\base.py", line 984, in execute
    return meth(self, multiparams, params)
  File "c:\users\super\knowland\knowland_start\lib\site-packages\sqlalchemy\sql\elements.py", line 293, in _execute_on_connection
    return connection._execute_clauseelement(self, multiparams, params)
  File "c:\users\super\knowland\knowland_start\lib\site-packages\sqlalchemy\engine\base.py", line 1097, in _execute_clauseelement
    ret = self._execute_context(
  File "c:\users\super\knowland\knowland_start\lib\site-packages\sqlalchemy\engine\base.py", line 1287, in _execute_context
    self._handle_dbapi_exception(
  File "c:\users\super\knowland\knowland_start\lib\site-packages\sqlalchemy\engine\base.py", line 1481, in _handle_dbapi_exception
    util.raise_(
  File "c:\users\super\knowland\knowland_start\lib\site-packages\sqlalchemy\util\compat.py", line 178, in raise_
    raise exception
  File "c:\users\super\knowland\knowland_start\lib\site-packages\sqlalchemy\engine\base.py", line 1247, in _execute_context
    self.dialect.do_execute(
  File "c:\users\super\knowland\knowland_start\lib\site-packages\sqlalchemy\engine\default.py", line 588, in do_execute
    cursor.execute(statement, parameters)
sqlalchemy.exc.OperationalError: (sqlite3.OperationalError) no such column: user.gpb_coin
[SQL: SELECT user.id AS user_id, user.username AS user_username, user.email AS user_email, user.password_hash AS user_password_hash, user.about_me AS user_about_me, user.last_seen AS user_last_seen, user.gpb_coin AS user_gpb_coin 
FROM user 
WHERE user.id = ?]
[parameters: (5,)]
(Background on this error at: http://sqlalche.me/e/e3q8)
